Workbook

Sheet Instrucciones
A1: Sistema de Inventario de Materiales
A2: Proyectos Eléctricos y de Plomería
A5: ¿Cómo funciona?
A6: 1. Catálogo de Materiales | B6: Aquí defines cada material, su unidad de medida y su stock mínimo. Es la base de todo el sistema.
A7: 2. Obras | B7: Lista de tus proyectos activos. Agrega una fila por cada obra nueva.
A8: 3. Movimientos | B8: AQUÍ REGISTRAS TODO, día a día. Cada vez que compras material, lo mandas a una obra, se consume, o regresa a bodega, agregas una fila aquí. Todo lo demás se calcula solo.
A9: 4. Inventario Bodega | B9: Se actualiza automáticamente. Te dice cuánto material tienes disponible en bodega central y te avisa si algo está por debajo del mínimo.
A10: 5. Inventario por Obra | B10: Selecciona una obra en la celda amarilla y verás automáticamente cuánto material se le ha enviado, cuánto se ha consumido, y cuánto queda disponible en esa obra.
A12: Código de colores
A13: Celdas amarillas | B13: Aquí escribes tú (datos de entrada). No modifiques nada fuera de estas celdas.
A14: Celdas blancas | B14: Se calculan solas con fórmulas. No las edites directamente.
A15: Rojo en Inventario Bodega | B15: Material por debajo del stock mínimo — hay que reabastecer.
A17: Tipos de movimiento (columna F en Movimientos)
A18: Entrada a Bodega | B18: Cuando compras material y llega a tu bodega central.
A19: Salida a Obra | B19: Cuando mandas material de bodega a una obra específica.
A20: Consumo en Obra | B20: Cuando el material se instala/usa y ya no está disponible.
A21: Devolución a Bodega | B21: Cuando sobra material en una obra y regresa a bodega.
A23: Tip | B23: Usa siempre el mismo Código de Material (columna C) — ahí viene de un menú desplegable tomado del Catálogo, para evitar errores de escritura.
A25: Control de Herramientas
A26: 6. Catálogo de Herramientas | B26: Lista de tus herramientas y equipo (escaleras, carretillas, rotomartillos, etc.) con código único por pieza.
A27: 7. Asignaciones Herramientas | B27: Registras aquí cada vez que una herramienta sale a una obra, regresa a bodega, o va a mantenimiento.
A28: 8. Ubicación Herramientas | B28: Se calcula sola tomando el ÚLTIMO movimiento de cada herramienta. Te dice dónde está cada una ahora mismo, y te marca en rojo si una herramienta lleva más tiempo en obra del que se esperaba (columna Alerta = RETRASADA).
A30: Cotizaciones
A31: 9. Datos Empresa | B31: Llena esto UNA SOLA VEZ: nombre, RFC, dirección, condiciones de pago, garantía, IVA. El Cotizador toma estos datos automáticamente.
A32: 10. Catálogo Precios Venta | B32: Tu lista de precios AL CLIENTE por unidad de trabajo instalado (material + mano de obra). Es distinto del Catálogo de Materiales, que es solo el costo del material.
A33: 11. Cotizador | B33: La plantilla lista para imprimir/enviar. Llena datos del cliente, agrega conceptos por código, y el subtotal/IVA/total se calculan solos. Para una cotización nueva, copia esta pestaña (clic derecho > Mover o copiar > Crear una copia).
A34: 12. Historial Cotizaciones | B34: Registra aquí el resumen de cada cotización enviada para dar seguimiento — cuáles están pendientes, aprobadas o rechazadas.

Sheet Datos Empresa
A1: Datos de la Empresa
A2: Llena estos datos una sola vez. El Cotizador los usa automaticamente.
A4: Nombre de la Empresa | B4: Instalaciones Electricas y Plomeria [Tu Empresa]
A5: RFC
A6: Direccion
A7: Ciudad, Estado | B7: Escobedo, Nuevo Leon
A8: Telefono
A9: Correo Electronico
A10: Sitio Web
A11: Tasa de IVA | B11: 0.16
A12: Dias de Validez de Cotizacion (default) | B12: 15
A13: Condiciones de Pago (default) | B13: 50% anticipo, 50% contra entrega
A14: Tiempo de Entrega (default) | B14: A convenir segun alcance
A15: Garantia (default) | B15: 90 dias en mano de obra

Sheet Catalogo Materiales
A1: Catálogo de Materiales
A2: Base de materiales, unidades y stock mínimo. Edita/agrega filas aquí.
A4: Código | B4: Material | C4: Categoría | D4: Unidad | E4: Costo Unitario Ref. | F4: Stock Mínimo
A5: MAT-001 | B5: Tubería PVC 1/2" | C5: Plomería | D5: m | E5: 18.5 | F5: 200
A6: MAT-002 | B6: Tubería PVC 3/4" | C6: Plomería | D6: m | E6: 24 | F6: 150
A7: MAT-003 | B7: Tubería Conduit EMT 1/2" | C7: Eléctrico | D7: m | E7: 22 | F7: 200
A8: MAT-004 | B8: Cable THHW Cal. 12 | C8: Eléctrico | D8: m | E8: 8.5 | F8: 500
A9: MAT-005 | B9: Cable THHW Cal. 10 | C9: Eléctrico | D9: m | E9: 12 | F9: 300
A10: MAT-006 | B10: Contacto Duplex Estándar | C10: Eléctrico | D10: pza | E10: 35 | F10: 100
A11: MAT-007 | B11: Contacto GFCI | C11: Eléctrico | D11: pza | E11: 180 | F11: 40
A12: MAT-008 | B12: Apagador Sencillo | C12: Eléctrico | D12: pza | E12: 30 | F12: 80
A13: MAT-009 | B13: Luminaria LED Empotrable 6" | C13: Eléctrico | D13: pza | E13: 220 | F13: 60
A14: MAT-010 | B14: Luminaria LED Panel 2x2 | C14: Eléctrico | D14: pza | E14: 450 | F14: 30
A15: MAT-011 | B15: Coples PVC 1/2" | C15: Plomería | D15: pza | E15: 4.5 | F15: 300
A16: MAT-012 | B16: Codo PVC 90° 1/2" | C16: Plomería | D16: pza | E16: 6 | F16: 250
... A24: MAT-020 | B24: Silicón Sanitario | C24: Plomería | D24: cartucho | E24: 45 | F24: 50

Sheet Obras
A1: Obras / Proyectos
A2: Lista de proyectos activos. Agrega una fila por cada obra nueva.
A4: Código Obra | B4: Nombre de Obra | C4: Cliente | D4: Responsable | E4: Estado | F4: Fecha Inicio
A5: OBRA-001 | B5: Edificio Corporativo Torre Norte | C5: Constructora ABC | D5: Ing. Ramírez | E5: Activa | F5: 2026-02-01
A6: OBRA-002 | B6: Plaza Comercial Los Pinos | C6: Grupo Inmobiliario XYZ | D6: Ing. Torres | E6: Activa | F6: 2026-04-15
A7: OBRA-003 | B7: Fraccionamiento Las Palmas Etapa 2 | C7: Desarrolladora Palmas | D7: Ing. Vega | E7: Activa | F7: 2026-05-10

Sheet Movimientos
A1: Movimientos de Material
A2: Registra aquí cada entrada, salida, consumo o devolución. Todo lo demás se calcula solo.
A4: ID | B4: Fecha | C4: Código Material | D4: Material | E4: Unidad | F4: Tipo de Movimiento | G4: Código Obra | H4: Nombre de Obra | I4: Cantidad | J4: Responsable | K4: Notas
A5: 1 | B5: 2026-06-02 | C5: MAT-001 | D5: =IFERROR(INDEX('Catalogo Materiales'!$B$5:$B$24,MATCH(C5,'Catalogo Materiales'!$A$5:$A$24,0)),"") -> Tubería PVC 1/2" | E5: =IFERROR(INDEX('Catalogo Materiales'!$D$5:$D$24,MATCH(C5,'Catalogo Materiales'!$A$5:$A$24,0)),"") -> m | F5: Entrada a Bodega | H5: =IFERROR(INDEX(Obras!$B$5:$B$54,MATCH(G5,Obras!$A$5:$A$54,0)),"") | I5: 400 | J5: Juan Pérez | K5: Compra inicial a proveedor
A6: 2 | B6: 2026-06-02 | C6: MAT-004 | D6: =IFERROR(INDEX('Catalogo Materiales'!$B$5:$B$24,MATCH(C6,'Catalogo Materiales'!$A$5:$A$24,0)),"") -> Cable THHW Cal. 12 | E6: =IFERROR(INDEX('Catalogo Materiales'!$D$5:$D$24,MATCH(C6,'Catalogo Materiales'!$A$5:$A$24,0)),"") -> m | F6: Entrada a Bodega | H6: =IFERROR(INDEX(Obras!$B$5:$B$54,MATCH(G6,Obras!$A$5:$A$54,0)),"") | I6: 1000 | J6: Juan Pérez | K6: Compra inicial a proveedor
A7: 3 | B7: 2026-06-03 | C7: MAT-009 | D7: =IFERROR(INDEX('Catalogo Materiales'!$B$5:$B$24,MATCH(C7,'Catalogo Materiales'!$A$5:$A$24,0)),"") -> Luminaria LED Empotrable 6" | E7: =IFERROR(INDEX('Catalogo Materiales'!$D$5:$D$24,MATCH(C7,'Catalogo Materiales'!$A$5:$A$24,0)),"") -> pza | F7: Entrada a Bodega | H7: =IFERROR(INDEX(Obras!$B$5:$B$54,MATCH(G7,Obras!$A$5:$A$54,0)),"") | I7: 80 | J7: Juan Pérez | K7: Compra inicial a proveedor
A8: 4 | B8: 2026-06-05 | C8: MAT-001 | D8: =IFERROR(INDEX('Catalogo Materiales'!$B$5:$B$24,MATCH(C8,'Catalogo Materiales'!$A$5:$A$24,0)),"") -> Tubería PVC 1/2" | E8: =IFERROR(INDEX('Catalogo Materiales'!$D$5:$D$24,MATCH(C8,'Catalogo Materiales'!$A$5:$A$24,0)),"") -> m | F8: Salida a Obra | G8: OBRA-001 | H8: =IFERROR(INDEX(Obras!$B$5:$B$54,MATCH(G8,Obras!$A$5:$A$54,0)),"") -> Edificio Corporativo Torre Norte | I8: 150 | J8: Carlos Ruiz | K8: Envío inicial plomería
A9: 5 | B9: 2026-06-05 | C9: MAT-004 | D9: =IFERROR(INDEX('Catalogo Materiales'!$B$5:$B$24,MATCH(C9,'Catalogo Materiales'!$A$5:$A$24,0)),"") -> Cable THHW Cal. 12 | E9: =IFERROR(INDEX('Catalogo Materiales'!$D$5:$D$24,MATCH(C9,'Catalogo Materiales'!$A$5:$A$24,0)),"") -> m | F9: Salida a Obra | G9: OBRA-001 | H9: =IFERROR(INDEX(Obras!$B$5:$B$54,MATCH(G9,Obras!$A$5:$A$54,0)),"") -> Edificio Corporativo Torre Norte | I9: 300 | J9: Carlos Ruiz | K9: Envío inicial eléctrico
A10: 6 | B10: 2026-06-10 | C10: MAT-004 | D10: =IFERROR(INDEX('Catalogo Materiales'!$B$5:$B$24,MATCH(C10,'Catalogo Materiales'!$A$5:$A$24,0)),"") -> Cable THHW Cal. 12 | E10: =IFERROR(INDEX('Catalogo Materiales'!$D$5:$D$24,MATCH(C10,'Catalogo Materiales'!$A$5:$A$24,0)),"") -> m | F10: Consumo en Obra | G10: OBRA-001 | H10: =IFERROR(INDEX(Obras!$B$5:$B$54,MATCH(G10,Obras!$A$5:$A$54,0)),"") -> Edificio Corporativo Torre Norte | I10: 180 | J10: Cuadrilla A | K10: Instalación primer piso
A11: 7 | B11: 2026-06-12 | C11: MAT-001 | D11: =IFERROR(INDEX('Catalogo Materiales'!$B$5:$B$24,MATCH(C11,'Catalogo Materiales'!$A$5:$A$24,0)),"") -> Tubería PVC 1/2" | E11: =IFERROR(INDEX('Catalogo Materiales'!$D$5:$D$24,MATCH(C11,'Catalogo Materiales'!$A$5:$A$24,0)),"") -> m | F11: Consumo en Obra | G11: OBRA-001 | H11: =IFERROR(INDEX(Obras!$B$5:$B$54,MATCH(G11,Obras!$A$5:$A$54,0)),"") -> Edificio Corporativo Torre Norte | I11: 90 | J11: Cuadrilla B | K11: Instalación baños
A12: 8 | B12: 2026-06-14 | C12: MAT-001 | D12: =IFERROR(INDEX('Catalogo Materiales'!$B$5:$B$24,MATCH(C12,'Catalogo Materiales'!$A$5:$A$24,0)),"") -> Tubería PVC 1/2" | E12: =IFERROR(INDEX('Catalogo Materiales'!$D$5:$D$24,MATCH(C12,'Catalogo Materiales'!$A$5:$A$24,0)),"") -> m | F12: Devolucion a Bodega | G12: OBRA-001 | H12: =IFERROR(INDEX(Obras!$B$5:$B$54,MATCH(G12,Obras!$A$5:$A$54,0)),"") -> Edificio Corporativo Torre Norte | I12: 10 | J12: Carlos Ruiz | K12: Sobrante de tuberia
A13: 9 | B13: 2026-06-15 | C13: MAT-009 | D13: =IFERROR(INDEX('Catalogo Materiales'!$B$5:$B$24,MATCH(C13,'Catalogo Materiales'!$A$5:$A$24,0)),"") -> Luminaria LED Empotrable 6" | E13: =IFERROR(INDEX('Catalogo Materiales'!$D$5:$D$24,MATCH(C13,'Catalogo Materiales'!$A$5:$A$24,0)),"") -> pza | F13: Salida a Obra | G13: OBRA-002 | H13: =IFERROR(INDEX(Obras!$B$5:$B$54,MATCH(G13,Obras!$A$5:$A$54,0)),"") -> Plaza Comercial Los Pinos | I13: 40 | J13: Carlos Ruiz | K13: Luminarias plaza comercial
D14: =IFERROR(INDEX('Catalogo Materiales'!$B$5:$B$24,MATCH(C14,'Catalogo Materiales'!$A$5:$A$24,0)),"") | E14: =IFERROR(INDEX('Catalogo Materiales'!$D$5:$D$24,MATCH(C14,'Catalogo Materiales'!$A$5:$A$24,0)),"") | H14: =IFERROR(INDEX(Obras!$B$5:$B$54,MATCH(G14,Obras!$A$5:$A$54,0)),"")
D15: =IFERROR(INDEX('Catalogo Materiales'!$B$5:$B$24,MATCH(C15,'Catalogo Materiales'!$A$5:$A$24,0)),"") | E15: =IFERROR(INDEX('Catalogo Materiales'!$D$5:$D$24,MATCH(C15,'Catalogo Materiales'!$A$5:$A$24,0)),"") | H15: =IFERROR(INDEX(Obras!$B$5:$B$54,MATCH(G15,Obras!$A$5:$A$54,0)),"")
D16: =IFERROR(INDEX('Catalogo Materiales'!$B$5:$B$24,MATCH(C16,'Catalogo Materiales'!$A$5:$A$24,0)),"") | E16: =IFERROR(INDEX('Catalogo Materiales'!$D$5:$D$24,MATCH(C16,'Catalogo Materiales'!$A$5:$A$24,0)),"") | H16: =IFERROR(INDEX(Obras!$B$5:$B$54,MATCH(G16,Obras!$A$5:$A$54,0)),"")
D17: =IFERROR(INDEX('Catalogo Materiales'!$B$5:$B$24,MATCH(C17,'Catalogo Materiales'!$A$5:$A$24,0)),"") | E17: =IFERROR(INDEX('Catalogo Materiales'!$D$5:$D$24,MATCH(C17,'Catalogo Materiales'!$A$5:$A$24,0)),"") | H17: =IFERROR(INDEX(Obras!$B$5:$B$54,MATCH(G17,Obras!$A$5:$A$54,0)),"")
D18: =IFERROR(INDEX('Catalogo Materiales'!$B$5:$B$24,MATCH(C18,'Catalogo Materiales'!$A$5:$A$24,0)),"") | E18: =IFERROR(INDEX('Catalogo Materiales'!$D$5:$D$24,MATCH(C18,'Catalogo Materiales'!$A$5:$A$24,0)),"") | H18: =IFERROR(INDEX(Obras!$B$5:$B$54,MATCH(G18,Obras!$A$5:$A$54,0)),"")
D19: =IFERROR(INDEX('Catalogo Materiales'!$B$5:$B$24,MATCH(C19,'Catalogo Materiales'!$A$5:$A$24,0)),"") | E19: =IFERROR(INDEX('Catalogo Materiales'!$D$5:$D$24,MATCH(C19,'Catalogo Materiales'!$A$5:$A$24,0)),"") | H19: =IFERROR(INDEX(Obras!$B$5:$B$54,MATCH(G19,Obras!$A$5:$A$54,0)),"")
D20: =IFERROR(INDEX('Catalogo Materiales'!$B$5:$B$24,MATCH(C20,'Catalogo Materiales'!$A$5:$A$24,0)),"") | E20: =IFERROR(INDEX('Catalogo Materiales'!$D$5:$D$24,MATCH(C20,'Catalogo Materiales'!$A$5:$A$24,0)),"") | H20: =IFERROR(INDEX(Obras!$B$5:$B$54,MATCH(G20,Obras!$A$5:$A$54,0)),"")
D21: =IFERROR(INDEX('Catalogo Materiales'!$B$5:$B$24,MATCH(C21,'Catalogo Materiales'!$A$5:$A$24,0)),"") | E21: =IFERROR(INDEX('Catalogo Materiales'!$D$5:$D$24,MATCH(C21,'Catalogo Materiales'!$A$5:$A$24,0)),"") | H21: =IFERROR(INDEX(Obras!$B$5:$B$54,MATCH(G21,Obras!$A$5:$A$54,0)),"")
D22: =IFERROR(INDEX('Catalogo Materiales'!$B$5:$B$24,MATCH(C22,'Catalogo Materiales'!$A$5:$A$24,0)),"") | E22: =IFERROR(INDEX('Catalogo Materiales'!$D$5:$D$24,MATCH(C22,'Catalogo Materiales'!$A$5:$A$24,0)),"") | H22: =IFERROR(INDEX(Obras!$B$5:$B$54,MATCH(G22,Obras!$A$5:$A$54,0)),"")
D23: =IFERROR(INDEX('Catalogo Materiales'!$B$5:$B$24,MATCH(C23,'Catalogo Materiales'!$A$5:$A$24,0)),"") | E23: =IFERROR(INDEX('Catalogo Materiales'!$D$5:$D$24,MATCH(C23,'Catalogo Materiales'!$A$5:$A$24,0)),"") | H23: =IFERROR(INDEX(Obras!$B$5:$B$54,MATCH(G23,Obras!$A$5:$A$54,0)),"")
D24: =IFERROR(INDEX('Catalogo Materiales'!$B$5:$B$24,MATCH(C24,'Catalogo Materiales'!$A$5:$A$24,0)),"") | E24: =IFERROR(INDEX('Catalogo Materiales'!$D$5:$D$24,MATCH(C24,'Catalogo Materiales'!$A$5:$A$24,0)),"") | H24: =IFERROR(INDEX(Obras!$B$5:$B$54,MATCH(G24,Obras!$A$5:$A$54,0)),"")
D25: =IFERROR(INDEX('Catalogo Materiales'!$B$5:$B$24,MATCH(C25,'Catalogo Materiales'!$A$5:$A$24,0)),"") | E25: =IFERROR(INDEX('Catalogo Materiales'!$D$5:$D$24,MATCH(C25,'Catalogo Materiales'!$A$5:$A$24,0)),"") | H25: =IFERROR(INDEX(Obras!$B$5:$B$54,MATCH(G25,Obras!$A$5:$A$54,0)),"")
... D60: =IFERROR(INDEX('Catalogo Materiales'!$B$5:$B$24,MATCH(C60,'Catalogo Materiales'!$A$5:$A$24,0)),"") | E60: =IFERROR(INDEX('Catalogo Materiales'!$D$5:$D$24,MATCH(C60,'Catalogo Materiales'!$A$5:$A$24,0)),"") | H60: =IFERROR(INDEX(Obras!$B$5:$B$54,MATCH(G60,Obras!$A$5:$A$54,0)),"")

Sheet Inventario Bodega
A1: Inventario de Bodega Central
A2: Se calcula automaticamente a partir de la hoja Movimientos. No editar manualmente.
A4: Codigo | B4: Material | C4: Categoria | D4: Unidad | E4: Entradas a Bodega | F4: Salidas a Obra | G4: Devoluciones a Bodega | H4: Stock Actual | I4: Stock Minimo | J4: Estado
A5: ='Catalogo Materiales'!A5 -> MAT-001 | B5: ='Catalogo Materiales'!B5 -> Tubería PVC 1/2" | C5: ='Catalogo Materiales'!C5 -> Plomería | D5: ='Catalogo Materiales'!D5 -> m | E5: =SUMIFS(Movimientos!$I$5:$I$60,Movimientos!$C$5:$C$60,A5,Movimientos!$F$5:$F$60,"Entrada a Bodega") -> 400 | F5: =SUMIFS(Movimientos!$I$5:$I$60,Movimientos!$C$5:$C$60,A5,Movimientos!$F$5:$F$60,"Salida a Obra") -> 150 | G5: =SUMIFS(Movimientos!$I$5:$I$60,Movimientos!$C$5:$C$60,A5,Movimientos!$F$5:$F$60,"Devolucion a Bodega") -> 10 | H5: =E5-F5+G5 -> 260 | I5: ='Catalogo Materiales'!F5 -> 200 | J5: =IF(H5<I5,"REABASTECER","OK") -> OK
A6: ='Catalogo Materiales'!A6 -> MAT-002 | B6: ='Catalogo Materiales'!B6 -> Tubería PVC 3/4" | C6: ='Catalogo Materiales'!C6 -> Plomería | D6: ='Catalogo Materiales'!D6 -> m | E6: =SUMIFS(Movimientos!$I$5:$I$60,Movimientos!$C$5:$C$60,A6,Movimientos!$F$5:$F$60,"Entrada a Bodega") -> 0 | F6: =SUMIFS(Movimientos!$I$5:$I$60,Movimientos!$C$5:$C$60,A6,Movimientos!$F$5:$F$60,"Salida a Obra") -> 0 | G6: =SUMIFS(Movimientos!$I$5:$I$60,Movimientos!$C$5:$C$60,A6,Movimientos!$F$5:$F$60,"Devolucion a Bodega") -> 0 | H6: =E6-F6+G6 -> 0 | I6: ='Catalogo Materiales'!F6 -> 150 | J6: =IF(H6<I6,"REABASTECER","OK") -> REABASTECER
A7: ='Catalogo Materiales'!A7 -> MAT-003 | B7: ='Catalogo Materiales'!B7 -> Tubería Conduit EMT 1/2" | C7: ='Catalogo Materiales'!C7 -> Eléctrico | D7: ='Catalogo Materiales'!D7 -> m | E7: =SUMIFS(Movimientos!$I$5:$I$60,Movimientos!$C$5:$C$60,A7,Movimientos!$F$5:$F$60,"Entrada a Bodega") -> 0 | F7: =SUMIFS(Movimientos!$I$5:$I$60,Movimientos!$C$5:$C$60,A7,Movimientos!$F$5:$F$60,"Salida a Obra") -> 0 | G7: =SUMIFS(Movimientos!$I$5:$I$60,Movimientos!$C$5:$C$60,A7,Movimientos!$F$5:$F$60,"Devolucion a Bodega") -> 0 | H7: =E7-F7+G7 -> 0 | I7: ='Catalogo Materiales'!F7 -> 200 | J7: =IF(H7<I7,"REABASTECER","OK") -> REABASTECER
A8: ='Catalogo Materiales'!A8 -> MAT-004 | B8: ='Catalogo Materiales'!B8 -> Cable THHW Cal. 12 | C8: ='Catalogo Materiales'!C8 -> Eléctrico | D8: ='Catalogo Materiales'!D8 -> m | E8: =SUMIFS(Movimientos!$I$5:$I$60,Movimientos!$C$5:$C$60,A8,Movimientos!$F$5:$F$60,"Entrada a Bodega") -> 1000 | F8: =SUMIFS(Movimientos!$I$5:$I$60,Movimientos!$C$5:$C$60,A8,Movimientos!$F$5:$F$60,"Salida a Obra") -> 300 | G8: =SUMIFS(Movimientos!$I$5:$I$60,Movimientos!$C$5:$C$60,A8,Movimientos!$F$5:$F$60,"Devolucion a Bodega") -> 0 | H8: =E8-F8+G8 -> 700 | I8: ='Catalogo Materiales'!F8 -> 500 | J8: =IF(H8<I8,"REABASTECER","OK") -> OK
A9: ='Catalogo Materiales'!A9 -> MAT-005 | B9: ='Catalogo Materiales'!B9 -> Cable THHW Cal. 10 | C9: ='Catalogo Materiales'!C9 -> Eléctrico | D9: ='Catalogo Materiales'!D9 -> m | E9: =SUMIFS(Movimientos!$I$5:$I$60,Movimientos!$C$5:$C$60,A9,Movimientos!$F$5:$F$60,"Entrada a Bodega") -> 0 | F9: =SUMIFS(Movimientos!$I$5:$I$60,Movimientos!$C$5:$C$60,A9,Movimientos!$F$5:$F$60,"Salida a Obra") -> 0 | G9: =SUMIFS(Movimientos!$I$5:$I$60,Movimientos!$C$5:$C$60,A9,Movimientos!$F$5:$F$60,"Devolucion a Bodega") -> 0 | H9: =E9-F9+G9 -> 0 | I9: ='Catalogo Materiales'!F9 -> 300 | J9: =IF(H9<I9,"REABASTECER","OK") -> REABASTECER
A10: ='Catalogo Materiales'!A10 -> MAT-006 | B10: ='Catalogo Materiales'!B10 -> Contacto Duplex Estándar | C10: ='Catalogo Materiales'!C10 -> Eléctrico | D10: ='Catalogo Materiales'!D10 -> pza | E10: =SUMIFS(Movimientos!$I$5:$I$60,Movimientos!$C$5:$C$60,A10,Movimientos!$F$5:$F$60,"Entrada a Bodega") -> 0 | F10: =SUMIFS(Movimientos!$I$5:$I$60,Movimientos!$C$5:$C$60,A10,Movimientos!$F$5:$F$60,"Salida a Obra") -> 0 | G10: =SUMIFS(Movimientos!$I$5:$I$60,Movimientos!$C$5:$C$60,A10,Movimientos!$F$5:$F$60,"Devolucion a Bodega") -> 0 | H10: =E10-F10+G10 -> 0 | I10: ='Catalogo Materiales'!F10 -> 100 | J10: =IF(H10<I10,"REABASTECER","OK") -> REABASTECER
A11: ='Catalogo Materiales'!A11 -> MAT-007 | B11: ='Catalogo Materiales'!B11 -> Contacto GFCI | C11: ='Catalogo Materiales'!C11 -> Eléctrico | D11: ='Catalogo Materiales'!D11 -> pza | E11: =SUMIFS(Movimientos!$I$5:$I$60,Movimientos!$C$5:$C$60,A11,Movimientos!$F$5:$F$60,"Entrada a Bodega") -> 0 | F11: =SUMIFS(Movimientos!$I$5:$I$60,Movimientos!$C$5:$C$60,A11,Movimientos!$F$5:$F$60,"Salida a Obra") -> 0 | G11: =SUMIFS(Movimientos!$I$5:$I$60,Movimientos!$C$5:$C$60,A11,Movimientos!$F$5:$F$60,"Devolucion a Bodega") -> 0 | H11: =E11-F11+G11 -> 0 | I11: ='Catalogo Materiales'!F11 -> 40 | J11: =IF(H11<I11,"REABASTECER","OK") -> REABASTECER
A12: ='Catalogo Materiales'!A12 -> MAT-008 | B12: ='Catalogo Materiales'!B12 -> Apagador Sencillo | C12: ='Catalogo Materiales'!C12 -> Eléctrico | D12: ='Catalogo Materiales'!D12 -> pza | E12: =SUMIFS(Movimientos!$I$5:$I$60,Movimientos!$C$5:$C$60,A12,Movimientos!$F$5:$F$60,"Entrada a Bodega") -> 0 | F12: =SUMIFS(Movimientos!$I$5:$I$60,Movimientos!$C$5:$C$60,A12,Movimientos!$F$5:$F$60,"Salida a Obra") -> 0 | G12: =SUMIFS(Movimientos!$I$5:$I$60,Movimientos!$C$5:$C$60,A12,Movimientos!$F$5:$F$60,"Devolucion a Bodega") -> 0 | H12: =E12-F12+G12 -> 0 | I12: ='Catalogo Materiales'!F12 -> 80 | J12: =IF(H12<I12,"REABASTECER","OK") -> REABASTECER
A13: ='Catalogo Materiales'!A13 -> MAT-009 | B13: ='Catalogo Materiales'!B13 -> Luminaria LED Empotrable 6" | C13: ='Catalogo Materiales'!C13 -> Eléctrico | D13: ='Catalogo Materiales'!D13 -> pza | E13: =SUMIFS(Movimientos!$I$5:$I$60,Movimientos!$C$5:$C$60,A13,Movimientos!$F$5:$F$60,"Entrada a Bodega") -> 80 | F13: =SUMIFS(Movimientos!$I$5:$I$60,Movimientos!$C$5:$C$60,A13,Movimientos!$F$5:$F$60,"Salida a Obra") -> 40 | G13: =SUMIFS(Movimientos!$I$5:$I$60,Movimientos!$C$5:$C$60,A13,Movimientos!$F$5:$F$60,"Devolucion a Bodega") -> 0 | H13: =E13-F13+G13 -> 40 | I13: ='Catalogo Materiales'!F13 -> 60 | J13: =IF(H13<I13,"REABASTECER","OK") -> REABASTECER
A14: ='Catalogo Materiales'!A14 -> MAT-010 | B14: ='Catalogo Materiales'!B14 -> Luminaria LED Panel 2x2 | C14: ='Catalogo Materiales'!C14 -> Eléctrico | D14: ='Catalogo Materiales'!D14 -> pza | E14: =SUMIFS(Movimientos!$I$5:$I$60,Movimientos!$C$5:$C$60,A14,Movimientos!$F$5:$F$60,"Entrada a Bodega") -> 0 | F14: =SUMIFS(Movimientos!$I$5:$I$60,Movimientos!$C$5:$C$60,A14,Movimientos!$F$5:$F$60,"Salida a Obra") -> 0 | G14: =SUMIFS(Movimientos!$I$5:$I$60,Movimientos!$C$5:$C$60,A14,Movimientos!$F$5:$F$60,"Devolucion a Bodega") -> 0 | H14: =E14-F14+G14 -> 0 | I14: ='Catalogo Materiales'!F14 -> 30 | J14: =IF(H14<I14,"REABASTECER","OK") -> REABASTECER
A15: ='Catalogo Materiales'!A15 -> MAT-011 | B15: ='Catalogo Materiales'!B15 -> Coples PVC 1/2" | C15: ='Catalogo Materiales'!C15 -> Plomería | D15: ='Catalogo Materiales'!D15 -> pza | E15: =SUMIFS(Movimientos!$I$5:$I$60,Movimientos!$C$5:$C$60,A15,Movimientos!$F$5:$F$60,"Entrada a Bodega") -> 0 | F15: =SUMIFS(Movimientos!$I$5:$I$60,Movimientos!$C$5:$C$60,A15,Movimientos!$F$5:$F$60,"Salida a Obra") -> 0 | G15: =SUMIFS(Movimientos!$I$5:$I$60,Movimientos!$C$5:$C$60,A15,Movimientos!$F$5:$F$60,"Devolucion a Bodega") -> 0 | H15: =E15-F15+G15 -> 0 | I15: ='Catalogo Materiales'!F15 -> 300 | J15: =IF(H15<I15,"REABASTECER","OK") -> REABASTECER
A16: ='Catalogo Materiales'!A16 -> MAT-012 | B16: ='Catalogo Materiales'!B16 -> Codo PVC 90° 1/2" | C16: ='Catalogo Materiales'!C16 -> Plomería | D16: ='Catalogo Materiales'!D16 -> pza | E16: =SUMIFS(Movimientos!$I$5:$I$60,Movimientos!$C$5:$C$60,A16,Movimientos!$F$5:$F$60,"Entrada a Bodega") -> 0 | F16: =SUMIFS(Movimientos!$I$5:$I$60,Movimientos!$C$5:$C$60,A16,Movimientos!$F$5:$F$60,"Salida a Obra") -> 0 | G16: =SUMIFS(Movimientos!$I$5:$I$60,Movimientos!$C$5:$C$60,A16,Movimientos!$F$5:$F$60,"Devolucion a Bodega") -> 0 | H16: =E16-F16+G16 -> 0 | I16: ='Catalogo Materiales'!F16 -> 250 | J16: =IF(H16<I16,"REABASTECER","OK") -> REABASTECER
... A24: ='Catalogo Materiales'!A24 -> MAT-020 | B24: ='Catalogo Materiales'!B24 -> Silicón Sanitario | C24: ='Catalogo Materiales'!C24 -> Plomería | D24: ='Catalogo Materiales'!D24 -> cartucho | E24: =SUMIFS(Movimientos!$I$5:$I$60,Movimientos!$C$5:$C$60,A24,Movimientos!$F$5:$F$60,"Entrada a Bodega") -> 0 | F24: =SUMIFS(Movimientos!$I$5:$I$60,Movimientos!$C$5:$C$60,A24,Movimientos!$F$5:$F$60,"Salida a Obra") -> 0 | G24: =SUMIFS(Movimientos!$I$5:$I$60,Movimientos!$C$5:$C$60,A24,Movimientos!$F$5:$F$60,"Devolucion a Bodega") -> 0 | H24: =E24-F24+G24 -> 0 | I24: ='Catalogo Materiales'!F24 -> 50 | J24: =IF(H24<I24,"REABASTECER","OK") -> REABASTECER

Sheet Inventario por Obra
A1: Inventario por Obra
A2: Selecciona una obra en la celda amarilla (B4) y veras su inventario disponible.
A4: Selecciona Obra: | B4: OBRA-001 | C4: Nombre: | D4: =IFERROR(INDEX(Obras!$B$5:$B$54,MATCH(B4,Obras!$A$5:$A$54,0)),"") -> Edificio Corporativo Torre Norte
A6: Codigo | B6: Material | C6: Unidad | D6: Enviado a Obra | E6: Consumido en Obra | F6: Devuelto a Bodega | G6: Disponible en Obra
A7: ='Catalogo Materiales'!A5 -> MAT-001 | B7: ='Catalogo Materiales'!B5 -> Tubería PVC 1/2" | C7: ='Catalogo Materiales'!D5 -> m | D7: =SUMIFS(Movimientos!$I$5:$I$60,Movimientos!$C$5:$C$60,A7,Movimientos!$G$5:$G$60,$B$4,Movimientos!$F$5:$F$60,"Salida a Obra") -> 150 | E7: =SUMIFS(Movimientos!$I$5:$I$60,Movimientos!$C$5:$C$60,A7,Movimientos!$G$5:$G$60,$B$4,Movimientos!$F$5:$F$60,"Consumo en Obra") -> 90 | F7: =SUMIFS(Movimientos!$I$5:$I$60,Movimientos!$C$5:$C$60,A7,Movimientos!$G$5:$G$60,$B$4,Movimientos!$F$5:$F$60,"Devolucion a Bodega") -> 10 | G7: =D7-E7-F7 -> 50
A8: ='Catalogo Materiales'!A6 -> MAT-002 | B8: ='Catalogo Materiales'!B6 -> Tubería PVC 3/4" | C8: ='Catalogo Materiales'!D6 -> m | D8: =SUMIFS(Movimientos!$I$5:$I$60,Movimientos!$C$5:$C$60,A8,Movimientos!$G$5:$G$60,$B$4,Movimientos!$F$5:$F$60,"Salida a Obra") -> 0 | E8: =SUMIFS(Movimientos!$I$5:$I$60,Movimientos!$C$5:$C$60,A8,Movimientos!$G$5:$G$60,$B$4,Movimientos!$F$5:$F$60,"Consumo en Obra") -> 0 | F8: =SUMIFS(Movimientos!$I$5:$I$60,Movimientos!$C$5:$C$60,A8,Movimientos!$G$5:$G$60,$B$4,Movimientos!$F$5:$F$60,"Devolucion a Bodega") -> 0 | G8: =D8-E8-F8 -> 0
A9: ='Catalogo Materiales'!A7 -> MAT-003 | B9: ='Catalogo Materiales'!B7 -> Tubería Conduit EMT 1/2" | C9: ='Catalogo Materiales'!D7 -> m | D9: =SUMIFS(Movimientos!$I$5:$I$60,Movimientos!$C$5:$C$60,A9,Movimientos!$G$5:$G$60,$B$4,Movimientos!$F$5:$F$60,"Salida a Obra") -> 0 | E9: =SUMIFS(Movimientos!$I$5:$I$60,Movimientos!$C$5:$C$60,A9,Movimientos!$G$5:$G$60,$B$4,Movimientos!$F$5:$F$60,"Consumo en Obra") -> 0 | F9: =SUMIFS(Movimientos!$I$5:$I$60,Movimientos!$C$5:$C$60,A9,Movimientos!$G$5:$G$60,$B$4,Movimientos!$F$5:$F$60,"Devolucion a Bodega") -> 0 | G9: =D9-E9-F9 -> 0
A10: ='Catalogo Materiales'!A8 -> MAT-004 | B10: ='Catalogo Materiales'!B8 -> Cable THHW Cal. 12 | C10: ='Catalogo Materiales'!D8 -> m | D10: =SUMIFS(Movimientos!$I$5:$I$60,Movimientos!$C$5:$C$60,A10,Movimientos!$G$5:$G$60,$B$4,Movimientos!$F$5:$F$60,"Salida a Obra") -> 300 | E10: =SUMIFS(Movimientos!$I$5:$I$60,Movimientos!$C$5:$C$60,A10,Movimientos!$G$5:$G$60,$B$4,Movimientos!$F$5:$F$60,"Consumo en Obra") -> 180 | F10: =SUMIFS(Movimientos!$I$5:$I$60,Movimientos!$C$5:$C$60,A10,Movimientos!$G$5:$G$60,$B$4,Movimientos!$F$5:$F$60,"Devolucion a Bodega") -> 0 | G10: =D10-E10-F10 -> 120
A11: ='Catalogo Materiales'!A9 -> MAT-005 | B11: ='Catalogo Materiales'!B9 -> Cable THHW Cal. 10 | C11: ='Catalogo Materiales'!D9 -> m | D11: =SUMIFS(Movimientos!$I$5:$I$60,Movimientos!$C$5:$C$60,A11,Movimientos!$G$5:$G$60,$B$4,Movimientos!$F$5:$F$60,"Salida a Obra") -> 0 | E11: =SUMIFS(Movimientos!$I$5:$I$60,Movimientos!$C$5:$C$60,A11,Movimientos!$G$5:$G$60,$B$4,Movimientos!$F$5:$F$60,"Consumo en Obra") -> 0 | F11: =SUMIFS(Movimientos!$I$5:$I$60,Movimientos!$C$5:$C$60,A11,Movimientos!$G$5:$G$60,$B$4,Movimientos!$F$5:$F$60,"Devolucion a Bodega") -> 0 | G11: =D11-E11-F11 -> 0
A12: ='Catalogo Materiales'!A10 -> MAT-006 | B12: ='Catalogo Materiales'!B10 -> Contacto Duplex Estándar | C12: ='Catalogo Materiales'!D10 -> pza | D12: =SUMIFS(Movimientos!$I$5:$I$60,Movimientos!$C$5:$C$60,A12,Movimientos!$G$5:$G$60,$B$4,Movimientos!$F$5:$F$60,"Salida a Obra") -> 0 | E12: =SUMIFS(Movimientos!$I$5:$I$60,Movimientos!$C$5:$C$60,A12,Movimientos!$G$5:$G$60,$B$4,Movimientos!$F$5:$F$60,"Consumo en Obra") -> 0 | F12: =SUMIFS(Movimientos!$I$5:$I$60,Movimientos!$C$5:$C$60,A12,Movimientos!$G$5:$G$60,$B$4,Movimientos!$F$5:$F$60,"Devolucion a Bodega") -> 0 | G12: =D12-E12-F12 -> 0
A13: ='Catalogo Materiales'!A11 -> MAT-007 | B13: ='Catalogo Materiales'!B11 -> Contacto GFCI | C13: ='Catalogo Materiales'!D11 -> pza | D13: =SUMIFS(Movimientos!$I$5:$I$60,Movimientos!$C$5:$C$60,A13,Movimientos!$G$5:$G$60,$B$4,Movimientos!$F$5:$F$60,"Salida a Obra") -> 0 | E13: =SUMIFS(Movimientos!$I$5:$I$60,Movimientos!$C$5:$C$60,A13,Movimientos!$G$5:$G$60,$B$4,Movimientos!$F$5:$F$60,"Consumo en Obra") -> 0 | F13: =SUMIFS(Movimientos!$I$5:$I$60,Movimientos!$C$5:$C$60,A13,Movimientos!$G$5:$G$60,$B$4,Movimientos!$F$5:$F$60,"Devolucion a Bodega") -> 0 | G13: =D13-E13-F13 -> 0
A14: ='Catalogo Materiales'!A12 -> MAT-008 | B14: ='Catalogo Materiales'!B12 -> Apagador Sencillo | C14: ='Catalogo Materiales'!D12 -> pza | D14: =SUMIFS(Movimientos!$I$5:$I$60,Movimientos!$C$5:$C$60,A14,Movimientos!$G$5:$G$60,$B$4,Movimientos!$F$5:$F$60,"Salida a Obra") -> 0 | E14: =SUMIFS(Movimientos!$I$5:$I$60,Movimientos!$C$5:$C$60,A14,Movimientos!$G$5:$G$60,$B$4,Movimientos!$F$5:$F$60,"Consumo en Obra") -> 0 | F14: =SUMIFS(Movimientos!$I$5:$I$60,Movimientos!$C$5:$C$60,A14,Movimientos!$G$5:$G$60,$B$4,Movimientos!$F$5:$F$60,"Devolucion a Bodega") -> 0 | G14: =D14-E14-F14 -> 0
A15: ='Catalogo Materiales'!A13 -> MAT-009 | B15: ='Catalogo Materiales'!B13 -> Luminaria LED Empotrable 6" | C15: ='Catalogo Materiales'!D13 -> pza | D15: =SUMIFS(Movimientos!$I$5:$I$60,Movimientos!$C$5:$C$60,A15,Movimientos!$G$5:$G$60,$B$4,Movimientos!$F$5:$F$60,"Salida a Obra") -> 0 | E15: =SUMIFS(Movimientos!$I$5:$I$60,Movimientos!$C$5:$C$60,A15,Movimientos!$G$5:$G$60,$B$4,Movimientos!$F$5:$F$60,"Consumo en Obra") -> 0 | F15: =SUMIFS(Movimientos!$I$5:$I$60,Movimientos!$C$5:$C$60,A15,Movimientos!$G$5:$G$60,$B$4,Movimientos!$F$5:$F$60,"Devolucion a Bodega") -> 0 | G15: =D15-E15-F15 -> 0
A16: ='Catalogo Materiales'!A14 -> MAT-010 | B16: ='Catalogo Materiales'!B14 -> Luminaria LED Panel 2x2 | C16: ='Catalogo Materiales'!D14 -> pza | D16: =SUMIFS(Movimientos!$I$5:$I$60,Movimientos!$C$5:$C$60,A16,Movimientos!$G$5:$G$60,$B$4,Movimientos!$F$5:$F$60,"Salida a Obra") -> 0 | E16: =SUMIFS(Movimientos!$I$5:$I$60,Movimientos!$C$5:$C$60,A16,Movimientos!$G$5:$G$60,$B$4,Movimientos!$F$5:$F$60,"Consumo en Obra") -> 0 | F16: =SUMIFS(Movimientos!$I$5:$I$60,Movimientos!$C$5:$C$60,A16,Movimientos!$G$5:$G$60,$B$4,Movimientos!$F$5:$F$60,"Devolucion a Bodega") -> 0 | G16: =D16-E16-F16 -> 0
A17: ='Catalogo Materiales'!A15 -> MAT-011 | B17: ='Catalogo Materiales'!B15 -> Coples PVC 1/2" | C17: ='Catalogo Materiales'!D15 -> pza | D17: =SUMIFS(Movimientos!$I$5:$I$60,Movimientos!$C$5:$C$60,A17,Movimientos!$G$5:$G$60,$B$4,Movimientos!$F$5:$F$60,"Salida a Obra") -> 0 | E17: =SUMIFS(Movimientos!$I$5:$I$60,Movimientos!$C$5:$C$60,A17,Movimientos!$G$5:$G$60,$B$4,Movimientos!$F$5:$F$60,"Consumo en Obra") -> 0 | F17: =SUMIFS(Movimientos!$I$5:$I$60,Movimientos!$C$5:$C$60,A17,Movimientos!$G$5:$G$60,$B$4,Movimientos!$F$5:$F$60,"Devolucion a Bodega") -> 0 | G17: =D17-E17-F17 -> 0
A18: ='Catalogo Materiales'!A16 -> MAT-012 | B18: ='Catalogo Materiales'!B16 -> Codo PVC 90° 1/2" | C18: ='Catalogo Materiales'!D16 -> pza | D18: =SUMIFS(Movimientos!$I$5:$I$60,Movimientos!$C$5:$C$60,A18,Movimientos!$G$5:$G$60,$B$4,Movimientos!$F$5:$F$60,"Salida a Obra") -> 0 | E18: =SUMIFS(Movimientos!$I$5:$I$60,Movimientos!$C$5:$C$60,A18,Movimientos!$G$5:$G$60,$B$4,Movimientos!$F$5:$F$60,"Consumo en Obra") -> 0 | F18: =SUMIFS(Movimientos!$I$5:$I$60,Movimientos!$C$5:$C$60,A18,Movimientos!$G$5:$G$60,$B$4,Movimientos!$F$5:$F$60,"Devolucion a Bodega") -> 0 | G18: =D18-E18-F18 -> 0
... A26: ='Catalogo Materiales'!A24 -> MAT-020 | B26: ='Catalogo Materiales'!B24 -> Silicón Sanitario | C26: ='Catalogo Materiales'!D24 -> cartucho | D26: =SUMIFS(Movimientos!$I$5:$I$60,Movimientos!$C$5:$C$60,A26,Movimientos!$G$5:$G$60,$B$4,Movimientos!$F$5:$F$60,"Salida a Obra") -> 0 | E26: =SUMIFS(Movimientos!$I$5:$I$60,Movimientos!$C$5:$C$60,A26,Movimientos!$G$5:$G$60,$B$4,Movimientos!$F$5:$F$60,"Consumo en Obra") -> 0 | F26: =SUMIFS(Movimientos!$I$5:$I$60,Movimientos!$C$5:$C$60,A26,Movimientos!$G$5:$G$60,$B$4,Movimientos!$F$5:$F$60,"Devolucion a Bodega") -> 0 | G26: =D26-E26-F26 -> 0

Sheet Catalogo Herramientas
A1: Catalogo de Herramientas y Equipo
A2: Cada herramienta con codigo unico. Edita/agrega filas aqui.
A4: Codigo | B4: Herramienta | C4: Categoria | D4: Marca / Modelo | E4: Valor Estimado | F4: Fecha Adquisicion | G4: Estado
A5: HER-001 | B5: Escalera de Aluminio 8 pies | C5: Escalera | D5: Werner | E5: 2800 | F5: 2023-03-10 | G5: Activa
A6: HER-002 | B6: Escalera de Aluminio 12 pies | C6: Escalera | D6: Werner | E6: 4200 | F6: 2023-03-10 | G6: Activa
A7: HER-003 | B7: Escalera de Tijera 6 pies | C7: Escalera | D7: Cuprum | E7: 1800 | F7: 2024-01-15 | G7: Activa
A8: HER-004 | B8: Carretilla de Obra | C8: Carretilla | D8: Truper | E8: 1500 | F8: 2022-08-20 | G8: Activa
A9: HER-005 | B9: Carretilla de Obra | C9: Carretilla | D9: Truper | E9: 1500 | F9: 2022-08-20 | G9: Activa
A10: HER-006 | B10: Rotomartillo SDS Plus | C10: Herramienta Electrica | D10: Bosch GBH 2-26 | E10: 4500 | F10: 2023-06-05 | G10: Activa
A11: HER-007 | B11: Rotomartillo SDS Plus | C11: Herramienta Electrica | D11: Bosch GBH 2-26 | E11: 4500 | F11: 2023-11-01 | G11: Activa
A12: HER-008 | B12: Taladro Percutor | C12: Herramienta Electrica | D12: DeWalt DCD996 | E12: 3200 | F12: 2023-06-05 | G12: Activa
A13: HER-009 | B13: Esmeriladora Angular | C13: Herramienta Electrica | D13: Makita 9557 | E13: 1800 | F13: 2024-02-10 | G13: Activa
A14: HER-010 | B14: Maquina Soldadora Inverter | C14: Soldadura | D14: Lincoln Electric | E14: 8500 | F14: 2022-05-15 | G14: Activa
A15: HER-011 | B15: Multimetro Digital | C15: Medicion | D15: Fluke 117 | E15: 2200 | F15: 2023-09-01 | G15: Activa
A16: HER-012 | B16: Detector de Voltaje | C16: Medicion | D16: Klein Tools | E16: 650 | F16: 2023-09-01 | G16: Activa
... A19: HER-015 | B19: Nivel Laser | C19: Medicion | D19: Bosch GLL 3-80 | E19: 3800 | F19: 2024-03-08 | G19: Activa

Sheet Asignaciones Herramientas
A1: Asignaciones de Herramientas
A2: Registra aqui cada vez que una herramienta sale, regresa, o va a mantenimiento. Todo lo demas se calcula solo.
A4: ID | B4: Fecha | C4: Codigo Herramienta | D4: Herramienta | E4: Tipo de Movimiento | F4: Codigo Obra | G4: Nombre de Obra | H4: Responsable | I4: Fecha Estimada Regreso | J4: Notas
A5: 1 | B5: 2026-06-01 | C5: HER-001 | D5: =IFERROR(INDEX('Catalogo Herramientas'!$B$5:$B$19,MATCH(C5,'Catalogo Herramientas'!$A$5:$A$19,0)),"") -> Escalera de Aluminio 8 pies | E5: Asignacion a Obra | F5: OBRA-001 | G5: =IFERROR(INDEX(Obras!$B$5:$B$54,MATCH(F5,Obras!$A$5:$A$54,0)),"") -> Edificio Corporativo Torre Norte | H5: Carlos Ruiz | I5: 2026-07-01 | J5: Escalera para trabajos en altura
A6: 2 | B6: 2026-06-01 | C6: HER-006 | D6: =IFERROR(INDEX('Catalogo Herramientas'!$B$5:$B$19,MATCH(C6,'Catalogo Herramientas'!$A$5:$A$19,0)),"") -> Rotomartillo SDS Plus | E6: Asignacion a Obra | F6: OBRA-001 | G6: =IFERROR(INDEX(Obras!$B$5:$B$54,MATCH(F6,Obras!$A$5:$A$54,0)),"") -> Edificio Corporativo Torre Norte | H6: Cuadrilla A | I6: 2026-07-01 | J6: Perforaciones muro de carga
A7: 3 | B7: 2026-06-03 | C7: HER-004 | D7: =IFERROR(INDEX('Catalogo Herramientas'!$B$5:$B$19,MATCH(C7,'Catalogo Herramientas'!$A$5:$A$19,0)),"") -> Carretilla de Obra | E7: Asignacion a Obra | F7: OBRA-002 | G7: =IFERROR(INDEX(Obras!$B$5:$B$54,MATCH(F7,Obras!$A$5:$A$54,0)),"") -> Plaza Comercial Los Pinos | H7: Carlos Ruiz | I7: 2026-06-30 | J7: Traslado de material
A8: 4 | B8: 2026-06-10 | C8: HER-013 | D8: =IFERROR(INDEX('Catalogo Herramientas'!$B$5:$B$19,MATCH(C8,'Catalogo Herramientas'!$A$5:$A$19,0)),"") -> Compresor de Aire Portatil | E8: Envio a Mantenimiento | G8: =IFERROR(INDEX(Obras!$B$5:$B$54,MATCH(F8,Obras!$A$5:$A$54,0)),"") | H8: Taller Externo | J8: Falla en compresor
A9: 5 | B9: 2026-06-15 | C9: HER-002 | D9: =IFERROR(INDEX('Catalogo Herramientas'!$B$5:$B$19,MATCH(C9,'Catalogo Herramientas'!$A$5:$A$19,0)),"") -> Escalera de Aluminio 12 pies | E9: Asignacion a Obra | F9: OBRA-003 | G9: =IFERROR(INDEX(Obras!$B$5:$B$54,MATCH(F9,Obras!$A$5:$A$54,0)),"") -> Fraccionamiento Las Palmas Etapa 2 | H9: Ing. Vega | I9: 2026-07-20
A10: 6 | B10: 2026-06-20 | C10: HER-006 | D10: =IFERROR(INDEX('Catalogo Herramientas'!$B$5:$B$19,MATCH(C10,'Catalogo Herramientas'!$A$5:$A$19,0)),"") -> Rotomartillo SDS Plus | E10: Regreso a Bodega | G10: =IFERROR(INDEX(Obras!$B$5:$B$54,MATCH(F10,Obras!$A$5:$A$54,0)),"") | H10: Cuadrilla A | J10: Trabajo terminado en OBRA-001
D11: =IFERROR(INDEX('Catalogo Herramientas'!$B$5:$B$19,MATCH(C11,'Catalogo Herramientas'!$A$5:$A$19,0)),"") | G11: =IFERROR(INDEX(Obras!$B$5:$B$54,MATCH(F11,Obras!$A$5:$A$54,0)),"")
D12: =IFERROR(INDEX('Catalogo Herramientas'!$B$5:$B$19,MATCH(C12,'Catalogo Herramientas'!$A$5:$A$19,0)),"") | G12: =IFERROR(INDEX(Obras!$B$5:$B$54,MATCH(F12,Obras!$A$5:$A$54,0)),"")
D13: =IFERROR(INDEX('Catalogo Herramientas'!$B$5:$B$19,MATCH(C13,'Catalogo Herramientas'!$A$5:$A$19,0)),"") | G13: =IFERROR(INDEX(Obras!$B$5:$B$54,MATCH(F13,Obras!$A$5:$A$54,0)),"")
D14: =IFERROR(INDEX('Catalogo Herramientas'!$B$5:$B$19,MATCH(C14,'Catalogo Herramientas'!$A$5:$A$19,0)),"") | G14: =IFERROR(INDEX(Obras!$B$5:$B$54,MATCH(F14,Obras!$A$5:$A$54,0)),"")
D15: =IFERROR(INDEX('Catalogo Herramientas'!$B$5:$B$19,MATCH(C15,'Catalogo Herramientas'!$A$5:$A$19,0)),"") | G15: =IFERROR(INDEX(Obras!$B$5:$B$54,MATCH(F15,Obras!$A$5:$A$54,0)),"")
D16: =IFERROR(INDEX('Catalogo Herramientas'!$B$5:$B$19,MATCH(C16,'Catalogo Herramientas'!$A$5:$A$19,0)),"") | G16: =IFERROR(INDEX(Obras!$B$5:$B$54,MATCH(F16,Obras!$A$5:$A$54,0)),"")
D17: =IFERROR(INDEX('Catalogo Herramientas'!$B$5:$B$19,MATCH(C17,'Catalogo Herramientas'!$A$5:$A$19,0)),"") | G17: =IFERROR(INDEX(Obras!$B$5:$B$54,MATCH(F17,Obras!$A$5:$A$54,0)),"")
D18: =IFERROR(INDEX('Catalogo Herramientas'!$B$5:$B$19,MATCH(C18,'Catalogo Herramientas'!$A$5:$A$19,0)),"") | G18: =IFERROR(INDEX(Obras!$B$5:$B$54,MATCH(F18,Obras!$A$5:$A$54,0)),"")
D19: =IFERROR(INDEX('Catalogo Herramientas'!$B$5:$B$19,MATCH(C19,'Catalogo Herramientas'!$A$5:$A$19,0)),"") | G19: =IFERROR(INDEX(Obras!$B$5:$B$54,MATCH(F19,Obras!$A$5:$A$54,0)),"")
D20: =IFERROR(INDEX('Catalogo Herramientas'!$B$5:$B$19,MATCH(C20,'Catalogo Herramientas'!$A$5:$A$19,0)),"") | G20: =IFERROR(INDEX(Obras!$B$5:$B$54,MATCH(F20,Obras!$A$5:$A$54,0)),"")
D21: =IFERROR(INDEX('Catalogo Herramientas'!$B$5:$B$19,MATCH(C21,'Catalogo Herramientas'!$A$5:$A$19,0)),"") | G21: =IFERROR(INDEX(Obras!$B$5:$B$54,MATCH(F21,Obras!$A$5:$A$54,0)),"")
D22: =IFERROR(INDEX('Catalogo Herramientas'!$B$5:$B$19,MATCH(C22,'Catalogo Herramientas'!$A$5:$A$19,0)),"") | G22: =IFERROR(INDEX(Obras!$B$5:$B$54,MATCH(F22,Obras!$A$5:$A$54,0)),"")
... D60: =IFERROR(INDEX('Catalogo Herramientas'!$B$5:$B$19,MATCH(C60,'Catalogo Herramientas'!$A$5:$A$19,0)),"") | G60: =IFERROR(INDEX(Obras!$B$5:$B$54,MATCH(F60,Obras!$A$5:$A$54,0)),"")

Sheet Ubicacion Herramientas
A1: Ubicacion Actual de Herramientas
A2: Se calcula automaticamente tomando el ultimo movimiento de cada herramienta. No editar manualmente.
A4: Codigo | B4: Herramienta | C4: Categoria | D4: Estado | E4: Obra Actual / Ubicacion | F4: Responsable Actual | G4: Fecha Ultimo Movimiento | H4: Fecha Estimada Regreso | I4: Alerta
A5: ='Catalogo Herramientas'!A5 -> HER-001 | B5: ='Catalogo Herramientas'!B5 -> Escalera de Aluminio 8 pies | C5: ='Catalogo Herramientas'!C5 -> Escalera | D5: =IF(L5="Sin Movimientos","Sin Movimientos",IF(L5="Asignacion a Obra","En Obra",IF(L5="Regreso a Bodega","En Bodega",IF(L5="Envio a Mantenimiento","En Mantenimiento",IF(L5="Regreso de Mantenimiento","En Bodega",""))))) -> En Obra | E5: =IF(K5=0,"",IF(D5="En Obra",IFERROR(INDEX('Asignaciones Herramientas'!$G$5:$G$60,MATCH(K5,'Asignaciones Herramientas'!$A$5:$A$60,0)),""),IF(D5="En Bodega","Bodega Central",IF(D5="En Mantenimiento","Taller / Mantenimiento","")))) -> Edificio Corporativo Torre Norte | F5: =IF(K5=0,"",IFERROR(INDEX('Asignaciones Herramientas'!$H$5:$H$60,MATCH(K5,'Asignaciones Herramientas'!$A$5:$A$60,0)),"")) -> Carlos Ruiz | G5: =IF(K5=0,"",IFERROR(INDEX('Asignaciones Herramientas'!$B$5:$B$60,MATCH(K5,'Asignaciones Herramientas'!$A$5:$A$60,0)),"")) -> 2026-06-01 | H5: =IF(OR(K5=0,IFERROR(INDEX('Asignaciones Herramientas'!$I$5:$I$60,MATCH(K5,'Asignaciones Herramientas'!$A$5:$A$60,0)),0)=0),"",INDEX('Asignaciones Herramientas'!$I$5:$I$60,MATCH(K5,'Asignaciones Herramientas'!$A$5:$A$60,0))) -> 2026-07-01 | I5: =IF(AND(D5="En Obra",H5<>"",H5<TODAY()),"RETRASADA","") | K5: =IFERROR(_xlfn.MAXIFS('Asignaciones Herramientas'!$A$5:$A$60,'Asignaciones Herramientas'!$C$5:$C$60,A5),0) -> 1 | L5: =IF(K5=0,"Sin Movimientos",IFERROR(INDEX('Asignaciones Herramientas'!$E$5:$E$60,MATCH(K5,'Asignaciones Herramientas'!$A$5:$A$60,0)),"")) -> Asignacion a Obra
A6: ='Catalogo Herramientas'!A6 -> HER-002 | B6: ='Catalogo Herramientas'!B6 -> Escalera de Aluminio 12 pies | C6: ='Catalogo Herramientas'!C6 -> Escalera | D6: =IF(L6="Sin Movimientos","Sin Movimientos",IF(L6="Asignacion a Obra","En Obra",IF(L6="Regreso a Bodega","En Bodega",IF(L6="Envio a Mantenimiento","En Mantenimiento",IF(L6="Regreso de Mantenimiento","En Bodega",""))))) -> En Obra | E6: =IF(K6=0,"",IF(D6="En Obra",IFERROR(INDEX('Asignaciones Herramientas'!$G$5:$G$60,MATCH(K6,'Asignaciones Herramientas'!$A$5:$A$60,0)),""),IF(D6="En Bodega","Bodega Central",IF(D6="En Mantenimiento","Taller / Mantenimiento","")))) -> Fraccionamiento Las Palmas Etapa 2 | F6: =IF(K6=0,"",IFERROR(INDEX('Asignaciones Herramientas'!$H$5:$H$60,MATCH(K6,'Asignaciones Herramientas'!$A$5:$A$60,0)),"")) -> Ing. Vega | G6: =IF(K6=0,"",IFERROR(INDEX('Asignaciones Herramientas'!$B$5:$B$60,MATCH(K6,'Asignaciones Herramientas'!$A$5:$A$60,0)),"")) -> 2026-06-15 | H6: =IF(OR(K6=0,IFERROR(INDEX('Asignaciones Herramientas'!$I$5:$I$60,MATCH(K6,'Asignaciones Herramientas'!$A$5:$A$60,0)),0)=0),"",INDEX('Asignaciones Herramientas'!$I$5:$I$60,MATCH(K6,'Asignaciones Herramientas'!$A$5:$A$60,0))) -> 2026-07-20 | I6: =IF(AND(D6="En Obra",H6<>"",H6<TODAY()),"RETRASADA","") | K6: =IFERROR(_xlfn.MAXIFS('Asignaciones Herramientas'!$A$5:$A$60,'Asignaciones Herramientas'!$C$5:$C$60,A6),0) -> 5 | L6: =IF(K6=0,"Sin Movimientos",IFERROR(INDEX('Asignaciones Herramientas'!$E$5:$E$60,MATCH(K6,'Asignaciones Herramientas'!$A$5:$A$60,0)),"")) -> Asignacion a Obra
A7: ='Catalogo Herramientas'!A7 -> HER-003 | B7: ='Catalogo Herramientas'!B7 -> Escalera de Tijera 6 pies | C7: ='Catalogo Herramientas'!C7 -> Escalera | D7: =IF(L7="Sin Movimientos","Sin Movimientos",IF(L7="Asignacion a Obra","En Obra",IF(L7="Regreso a Bodega","En Bodega",IF(L7="Envio a Mantenimiento","En Mantenimiento",IF(L7="Regreso de Mantenimiento","En Bodega",""))))) -> Sin Movimientos | E7: =IF(K7=0,"",IF(D7="En Obra",IFERROR(INDEX('Asignaciones Herramientas'!$G$5:$G$60,MATCH(K7,'Asignaciones Herramientas'!$A$5:$A$60,0)),""),IF(D7="En Bodega","Bodega Central",IF(D7="En Mantenimiento","Taller / Mantenimiento","")))) | F7: =IF(K7=0,"",IFERROR(INDEX('Asignaciones Herramientas'!$H$5:$H$60,MATCH(K7,'Asignaciones Herramientas'!$A$5:$A$60,0)),"")) | G7: =IF(K7=0,"",IFERROR(INDEX('Asignaciones Herramientas'!$B$5:$B$60,MATCH(K7,'Asignaciones Herramientas'!$A$5:$A$60,0)),"")) | H7: =IF(OR(K7=0,IFERROR(INDEX('Asignaciones Herramientas'!$I$5:$I$60,MATCH(K7,'Asignaciones Herramientas'!$A$5:$A$60,0)),0)=0),"",INDEX('Asignaciones Herramientas'!$I$5:$I$60,MATCH(K7,'Asignaciones Herramientas'!$A$5:$A$60,0))) | I7: =IF(AND(D7="En Obra",H7<>"",H7<TODAY()),"RETRASADA","") | K7: =IFERROR(_xlfn.MAXIFS('Asignaciones Herramientas'!$A$5:$A$60,'Asignaciones Herramientas'!$C$5:$C$60,A7),0) -> 0 | L7: =IF(K7=0,"Sin Movimientos",IFERROR(INDEX('Asignaciones Herramientas'!$E$5:$E$60,MATCH(K7,'Asignaciones Herramientas'!$A$5:$A$60,0)),"")) -> Sin Movimientos
A8: ='Catalogo Herramientas'!A8 -> HER-004 | B8: ='Catalogo Herramientas'!B8 -> Carretilla de Obra | C8: ='Catalogo Herramientas'!C8 -> Carretilla | D8: =IF(L8="Sin Movimientos","Sin Movimientos",IF(L8="Asignacion a Obra","En Obra",IF(L8="Regreso a Bodega","En Bodega",IF(L8="Envio a Mantenimiento","En Mantenimiento",IF(L8="Regreso de Mantenimiento","En Bodega",""))))) -> En Obra | E8: =IF(K8=0,"",IF(D8="En Obra",IFERROR(INDEX('Asignaciones Herramientas'!$G$5:$G$60,MATCH(K8,'Asignaciones Herramientas'!$A$5:$A$60,0)),""),IF(D8="En Bodega","Bodega Central",IF(D8="En Mantenimiento","Taller / Mantenimiento","")))) -> Plaza Comercial Los Pinos | F8: =IF(K8=0,"",IFERROR(INDEX('Asignaciones Herramientas'!$H$5:$H$60,MATCH(K8,'Asignaciones Herramientas'!$A$5:$A$60,0)),"")) -> Carlos Ruiz | G8: =IF(K8=0,"",IFERROR(INDEX('Asignaciones Herramientas'!$B$5:$B$60,MATCH(K8,'Asignaciones Herramientas'!$A$5:$A$60,0)),"")) -> 2026-06-03 | H8: =IF(OR(K8=0,IFERROR(INDEX('Asignaciones Herramientas'!$I$5:$I$60,MATCH(K8,'Asignaciones Herramientas'!$A$5:$A$60,0)),0)=0),"",INDEX('Asignaciones Herramientas'!$I$5:$I$60,MATCH(K8,'Asignaciones Herramientas'!$A$5:$A$60,0))) -> 2026-06-30 | I8: =IF(AND(D8="En Obra",H8<>"",H8<TODAY()),"RETRASADA","") | K8: =IFERROR(_xlfn.MAXIFS('Asignaciones Herramientas'!$A$5:$A$60,'Asignaciones Herramientas'!$C$5:$C$60,A8),0) -> 3 | L8: =IF(K8=0,"Sin Movimientos",IFERROR(INDEX('Asignaciones Herramientas'!$E$5:$E$60,MATCH(K8,'Asignaciones Herramientas'!$A$5:$A$60,0)),"")) -> Asignacion a Obra
A9: ='Catalogo Herramientas'!A9 -> HER-005 | B9: ='Catalogo Herramientas'!B9 -> Carretilla de Obra | C9: ='Catalogo Herramientas'!C9 -> Carretilla | D9: =IF(L9="Sin Movimientos","Sin Movimientos",IF(L9="Asignacion a Obra","En Obra",IF(L9="Regreso a Bodega","En Bodega",IF(L9="Envio a Mantenimiento","En Mantenimiento",IF(L9="Regreso de Mantenimiento","En Bodega",""))))) -> Sin Movimientos | E9: =IF(K9=0,"",IF(D9="En Obra",IFERROR(INDEX('Asignaciones Herramientas'!$G$5:$G$60,MATCH(K9,'Asignaciones Herramientas'!$A$5:$A$60,0)),""),IF(D9="En Bodega","Bodega Central",IF(D9="En Mantenimiento","Taller / Mantenimiento","")))) | F9: =IF(K9=0,"",IFERROR(INDEX('Asignaciones Herramientas'!$H$5:$H$60,MATCH(K9,'Asignaciones Herramientas'!$A$5:$A$60,0)),"")) | G9: =IF(K9=0,"",IFERROR(INDEX('Asignaciones Herramientas'!$B$5:$B$60,MATCH(K9,'Asignaciones Herramientas'!$A$5:$A$60,0)),"")) | H9: =IF(OR(K9=0,IFERROR(INDEX('Asignaciones Herramientas'!$I$5:$I$60,MATCH(K9,'Asignaciones Herramientas'!$A$5:$A$60,0)),0)=0),"",INDEX('Asignaciones Herramientas'!$I$5:$I$60,MATCH(K9,'Asignaciones Herramientas'!$A$5:$A$60,0))) | I9: =IF(AND(D9="En Obra",H9<>"",H9<TODAY()),"RETRASADA","") | K9: =IFERROR(_xlfn.MAXIFS('Asignaciones Herramientas'!$A$5:$A$60,'Asignaciones Herramientas'!$C$5:$C$60,A9),0) -> 0 | L9: =IF(K9=0,"Sin Movimientos",IFERROR(INDEX('Asignaciones Herramientas'!$E$5:$E$60,MATCH(K9,'Asignaciones Herramientas'!$A$5:$A$60,0)),"")) -> Sin Movimientos
A10: ='Catalogo Herramientas'!A10 -> HER-006 | B10: ='Catalogo Herramientas'!B10 -> Rotomartillo SDS Plus | C10: ='Catalogo Herramientas'!C10 -> Herramienta Electrica | D10: =IF(L10="Sin Movimientos","Sin Movimientos",IF(L10="Asignacion a Obra","En Obra",IF(L10="Regreso a Bodega","En Bodega",IF(L10="Envio a Mantenimiento","En Mantenimiento",IF(L10="Regreso de Mantenimiento","En Bodega",""))))) -> En Bodega | E10: =IF(K10=0,"",IF(D10="En Obra",IFERROR(INDEX('Asignaciones Herramientas'!$G$5:$G$60,MATCH(K10,'Asignaciones Herramientas'!$A$5:$A$60,0)),""),IF(D10="En Bodega","Bodega Central",IF(D10="En Mantenimiento","Taller / Mantenimiento","")))) -> Bodega Central | F10: =IF(K10=0,"",IFERROR(INDEX('Asignaciones Herramientas'!$H$5:$H$60,MATCH(K10,'Asignaciones Herramientas'!$A$5:$A$60,0)),"")) -> Cuadrilla A | G10: =IF(K10=0,"",IFERROR(INDEX('Asignaciones Herramientas'!$B$5:$B$60,MATCH(K10,'Asignaciones Herramientas'!$A$5:$A$60,0)),"")) -> 2026-06-20 | H10: =IF(OR(K10=0,IFERROR(INDEX('Asignaciones Herramientas'!$I$5:$I$60,MATCH(K10,'Asignaciones Herramientas'!$A$5:$A$60,0)),0)=0),"",INDEX('Asignaciones Herramientas'!$I$5:$I$60,MATCH(K10,'Asignaciones Herramientas'!$A$5:$A$60,0))) | I10: =IF(AND(D10="En Obra",H10<>"",H10<TODAY()),"RETRASADA","") | K10: =IFERROR(_xlfn.MAXIFS('Asignaciones Herramientas'!$A$5:$A$60,'Asignaciones Herramientas'!$C$5:$C$60,A10),0) -> 6 | L10: =IF(K10=0,"Sin Movimientos",IFERROR(INDEX('Asignaciones Herramientas'!$E$5:$E$60,MATCH(K10,'Asignaciones Herramientas'!$A$5:$A$60,0)),"")) -> Regreso a Bodega
A11: ='Catalogo Herramientas'!A11 -> HER-007 | B11: ='Catalogo Herramientas'!B11 -> Rotomartillo SDS Plus | C11: ='Catalogo Herramientas'!C11 -> Herramienta Electrica | D11: =IF(L11="Sin Movimientos","Sin Movimientos",IF(L11="Asignacion a Obra","En Obra",IF(L11="Regreso a Bodega","En Bodega",IF(L11="Envio a Mantenimiento","En Mantenimiento",IF(L11="Regreso de Mantenimiento","En Bodega",""))))) -> Sin Movimientos | E11: =IF(K11=0,"",IF(D11="En Obra",IFERROR(INDEX('Asignaciones Herramientas'!$G$5:$G$60,MATCH(K11,'Asignaciones Herramientas'!$A$5:$A$60,0)),""),IF(D11="En Bodega","Bodega Central",IF(D11="En Mantenimiento","Taller / Mantenimiento","")))) | F11: =IF(K11=0,"",IFERROR(INDEX('Asignaciones Herramientas'!$H$5:$H$60,MATCH(K11,'Asignaciones Herramientas'!$A$5:$A$60,0)),"")) | G11: =IF(K11=0,"",IFERROR(INDEX('Asignaciones Herramientas'!$B$5:$B$60,MATCH(K11,'Asignaciones Herramientas'!$A$5:$A$60,0)),"")) | H11: =IF(OR(K11=0,IFERROR(INDEX('Asignaciones Herramientas'!$I$5:$I$60,MATCH(K11,'Asignaciones Herramientas'!$A$5:$A$60,0)),0)=0),"",INDEX('Asignaciones Herramientas'!$I$5:$I$60,MATCH(K11,'Asignaciones Herramientas'!$A$5:$A$60,0))) | I11: =IF(AND(D11="En Obra",H11<>"",H11<TODAY()),"RETRASADA","") | K11: =IFERROR(_xlfn.MAXIFS('Asignaciones Herramientas'!$A$5:$A$60,'Asignaciones Herramientas'!$C$5:$C$60,A11),0) -> 0 | L11: =IF(K11=0,"Sin Movimientos",IFERROR(INDEX('Asignaciones Herramientas'!$E$5:$E$60,MATCH(K11,'Asignaciones Herramientas'!$A$5:$A$60,0)),"")) -> Sin Movimientos
A12: ='Catalogo Herramientas'!A12 -> HER-008 | B12: ='Catalogo Herramientas'!B12 -> Taladro Percutor | C12: ='Catalogo Herramientas'!C12 -> Herramienta Electrica | D12: =IF(L12="Sin Movimientos","Sin Movimientos",IF(L12="Asignacion a Obra","En Obra",IF(L12="Regreso a Bodega","En Bodega",IF(L12="Envio a Mantenimiento","En Mantenimiento",IF(L12="Regreso de Mantenimiento","En Bodega",""))))) -> Sin Movimientos | E12: =IF(K12=0,"",IF(D12="En Obra",IFERROR(INDEX('Asignaciones Herramientas'!$G$5:$G$60,MATCH(K12,'Asignaciones Herramientas'!$A$5:$A$60,0)),""),IF(D12="En Bodega","Bodega Central",IF(D12="En Mantenimiento","Taller / Mantenimiento","")))) | F12: =IF(K12=0,"",IFERROR(INDEX('Asignaciones Herramientas'!$H$5:$H$60,MATCH(K12,'Asignaciones Herramientas'!$A$5:$A$60,0)),"")) | G12: =IF(K12=0,"",IFERROR(INDEX('Asignaciones Herramientas'!$B$5:$B$60,MATCH(K12,'Asignaciones Herramientas'!$A$5:$A$60,0)),"")) | H12: =IF(OR(K12=0,IFERROR(INDEX('Asignaciones Herramientas'!$I$5:$I$60,MATCH(K12,'Asignaciones Herramientas'!$A$5:$A$60,0)),0)=0),"",INDEX('Asignaciones Herramientas'!$I$5:$I$60,MATCH(K12,'Asignaciones Herramientas'!$A$5:$A$60,0))) | I12: =IF(AND(D12="En Obra",H12<>"",H12<TODAY()),"RETRASADA","") | K12: =IFERROR(_xlfn.MAXIFS('Asignaciones Herramientas'!$A$5:$A$60,'Asignaciones Herramientas'!$C$5:$C$60,A12),0) -> 0 | L12: =IF(K12=0,"Sin Movimientos",IFERROR(INDEX('Asignaciones Herramientas'!$E$5:$E$60,MATCH(K12,'Asignaciones Herramientas'!$A$5:$A$60,0)),"")) -> Sin Movimientos
A13: ='Catalogo Herramientas'!A13 -> HER-009 | B13: ='Catalogo Herramientas'!B13 -> Esmeriladora Angular | C13: ='Catalogo Herramientas'!C13 -> Herramienta Electrica | D13: =IF(L13="Sin Movimientos","Sin Movimientos",IF(L13="Asignacion a Obra","En Obra",IF(L13="Regreso a Bodega","En Bodega",IF(L13="Envio a Mantenimiento","En Mantenimiento",IF(L13="Regreso de Mantenimiento","En Bodega",""))))) -> Sin Movimientos | E13: =IF(K13=0,"",IF(D13="En Obra",IFERROR(INDEX('Asignaciones Herramientas'!$G$5:$G$60,MATCH(K13,'Asignaciones Herramientas'!$A$5:$A$60,0)),""),IF(D13="En Bodega","Bodega Central",IF(D13="En Mantenimiento","Taller / Mantenimiento","")))) | F13: =IF(K13=0,"",IFERROR(INDEX('Asignaciones Herramientas'!$H$5:$H$60,MATCH(K13,'Asignaciones Herramientas'!$A$5:$A$60,0)),"")) | G13: =IF(K13=0,"",IFERROR(INDEX('Asignaciones Herramientas'!$B$5:$B$60,MATCH(K13,'Asignaciones Herramientas'!$A$5:$A$60,0)),"")) | H13: =IF(OR(K13=0,IFERROR(INDEX('Asignaciones Herramientas'!$I$5:$I$60,MATCH(K13,'Asignaciones Herramientas'!$A$5:$A$60,0)),0)=0),"",INDEX('Asignaciones Herramientas'!$I$5:$I$60,MATCH(K13,'Asignaciones Herramientas'!$A$5:$A$60,0))) | I13: =IF(AND(D13="En Obra",H13<>"",H13<TODAY()),"RETRASADA","") | K13: =IFERROR(_xlfn.MAXIFS('Asignaciones Herramientas'!$A$5:$A$60,'Asignaciones Herramientas'!$C$5:$C$60,A13),0) -> 0 | L13: =IF(K13=0,"Sin Movimientos",IFERROR(INDEX('Asignaciones Herramientas'!$E$5:$E$60,MATCH(K13,'Asignaciones Herramientas'!$A$5:$A$60,0)),"")) -> Sin Movimientos
A14: ='Catalogo Herramientas'!A14 -> HER-010 | B14: ='Catalogo Herramientas'!B14 -> Maquina Soldadora Inverter | C14: ='Catalogo Herramientas'!C14 -> Soldadura | D14: =IF(L14="Sin Movimientos","Sin Movimientos",IF(L14="Asignacion a Obra","En Obra",IF(L14="Regreso a Bodega","En Bodega",IF(L14="Envio a Mantenimiento","En Mantenimiento",IF(L14="Regreso de Mantenimiento","En Bodega",""))))) -> Sin Movimientos | E14: =IF(K14=0,"",IF(D14="En Obra",IFERROR(INDEX('Asignaciones Herramientas'!$G$5:$G$60,MATCH(K14,'Asignaciones Herramientas'!$A$5:$A$60,0)),""),IF(D14="En Bodega","Bodega Central",IF(D14="En Mantenimiento","Taller / Mantenimiento","")))) | F14: =IF(K14=0,"",IFERROR(INDEX('Asignaciones Herramientas'!$H$5:$H$60,MATCH(K14,'Asignaciones Herramientas'!$A$5:$A$60,0)),"")) | G14: =IF(K14=0,"",IFERROR(INDEX('Asignaciones Herramientas'!$B$5:$B$60,MATCH(K14,'Asignaciones Herramientas'!$A$5:$A$60,0)),"")) | H14: =IF(OR(K14=0,IFERROR(INDEX('Asignaciones Herramientas'!$I$5:$I$60,MATCH(K14,'Asignaciones Herramientas'!$A$5:$A$60,0)),0)=0),"",INDEX('Asignaciones Herramientas'!$I$5:$I$60,MATCH(K14,'Asignaciones Herramientas'!$A$5:$A$60,0))) | I14: =IF(AND(D14="En Obra",H14<>"",H14<TODAY()),"RETRASADA","") | K14: =IFERROR(_xlfn.MAXIFS('Asignaciones Herramientas'!$A$5:$A$60,'Asignaciones Herramientas'!$C$5:$C$60,A14),0) -> 0 | L14: =IF(K14=0,"Sin Movimientos",IFERROR(INDEX('Asignaciones Herramientas'!$E$5:$E$60,MATCH(K14,'Asignaciones Herramientas'!$A$5:$A$60,0)),"")) -> Sin Movimientos
A15: ='Catalogo Herramientas'!A15 -> HER-011 | B15: ='Catalogo Herramientas'!B15 -> Multimetro Digital | C15: ='Catalogo Herramientas'!C15 -> Medicion | D15: =IF(L15="Sin Movimientos","Sin Movimientos",IF(L15="Asignacion a Obra","En Obra",IF(L15="Regreso a Bodega","En Bodega",IF(L15="Envio a Mantenimiento","En Mantenimiento",IF(L15="Regreso de Mantenimiento","En Bodega",""))))) -> Sin Movimientos | E15: =IF(K15=0,"",IF(D15="En Obra",IFERROR(INDEX('Asignaciones Herramientas'!$G$5:$G$60,MATCH(K15,'Asignaciones Herramientas'!$A$5:$A$60,0)),""),IF(D15="En Bodega","Bodega Central",IF(D15="En Mantenimiento","Taller / Mantenimiento","")))) | F15: =IF(K15=0,"",IFERROR(INDEX('Asignaciones Herramientas'!$H$5:$H$60,MATCH(K15,'Asignaciones Herramientas'!$A$5:$A$60,0)),"")) | G15: =IF(K15=0,"",IFERROR(INDEX('Asignaciones Herramientas'!$B$5:$B$60,MATCH(K15,'Asignaciones Herramientas'!$A$5:$A$60,0)),"")) | H15: =IF(OR(K15=0,IFERROR(INDEX('Asignaciones Herramientas'!$I$5:$I$60,MATCH(K15,'Asignaciones Herramientas'!$A$5:$A$60,0)),0)=0),"",INDEX('Asignaciones Herramientas'!$I$5:$I$60,MATCH(K15,'Asignaciones Herramientas'!$A$5:$A$60,0))) | I15: =IF(AND(D15="En Obra",H15<>"",H15<TODAY()),"RETRASADA","") | K15: =IFERROR(_xlfn.MAXIFS('Asignaciones Herramientas'!$A$5:$A$60,'Asignaciones Herramientas'!$C$5:$C$60,A15),0) -> 0 | L15: =IF(K15=0,"Sin Movimientos",IFERROR(INDEX('Asignaciones Herramientas'!$E$5:$E$60,MATCH(K15,'Asignaciones Herramientas'!$A$5:$A$60,0)),"")) -> Sin Movimientos
A16: ='Catalogo Herramientas'!A16 -> HER-012 | B16: ='Catalogo Herramientas'!B16 -> Detector de Voltaje | C16: ='Catalogo Herramientas'!C16 -> Medicion | D16: =IF(L16="Sin Movimientos","Sin Movimientos",IF(L16="Asignacion a Obra","En Obra",IF(L16="Regreso a Bodega","En Bodega",IF(L16="Envio a Mantenimiento","En Mantenimiento",IF(L16="Regreso de Mantenimiento","En Bodega",""))))) -> Sin Movimientos | E16: =IF(K16=0,"",IF(D16="En Obra",IFERROR(INDEX('Asignaciones Herramientas'!$G$5:$G$60,MATCH(K16,'Asignaciones Herramientas'!$A$5:$A$60,0)),""),IF(D16="En Bodega","Bodega Central",IF(D16="En Mantenimiento","Taller / Mantenimiento","")))) | F16: =IF(K16=0,"",IFERROR(INDEX('Asignaciones Herramientas'!$H$5:$H$60,MATCH(K16,'Asignaciones Herramientas'!$A$5:$A$60,0)),"")) | G16: =IF(K16=0,"",IFERROR(INDEX('Asignaciones Herramientas'!$B$5:$B$60,MATCH(K16,'Asignaciones Herramientas'!$A$5:$A$60,0)),"")) | H16: =IF(OR(K16=0,IFERROR(INDEX('Asignaciones Herramientas'!$I$5:$I$60,MATCH(K16,'Asignaciones Herramientas'!$A$5:$A$60,0)),0)=0),"",INDEX('Asignaciones Herramientas'!$I$5:$I$60,MATCH(K16,'Asignaciones Herramientas'!$A$5:$A$60,0))) | I16: =IF(AND(D16="En Obra",H16<>"",H16<TODAY()),"RETRASADA","") | K16: =IFERROR(_xlfn.MAXIFS('Asignaciones Herramientas'!$A$5:$A$60,'Asignaciones Herramientas'!$C$5:$C$60,A16),0) -> 0 | L16: =IF(K16=0,"Sin Movimientos",IFERROR(INDEX('Asignaciones Herramientas'!$E$5:$E$60,MATCH(K16,'Asignaciones Herramientas'!$A$5:$A$60,0)),"")) -> Sin Movimientos
... A19: ='Catalogo Herramientas'!A19 -> HER-015 | B19: ='Catalogo Herramientas'!B19 -> Nivel Laser | C19: ='Catalogo Herramientas'!C19 -> Medicion | D19: =IF(L19="Sin Movimientos","Sin Movimientos",IF(L19="Asignacion a Obra","En Obra",IF(L19="Regreso a Bodega","En Bodega",IF(L19="Envio a Mantenimiento","En Mantenimiento",IF(L19="Regreso de Mantenimiento","En Bodega",""))))) -> Sin Movimientos | E19: =IF(K19=0,"",IF(D19="En Obra",IFERROR(INDEX('Asignaciones Herramientas'!$G$5:$G$60,MATCH(K19,'Asignaciones Herramientas'!$A$5:$A$60,0)),""),IF(D19="En Bodega","Bodega Central",IF(D19="En Mantenimiento","Taller / Mantenimiento","")))) | F19: =IF(K19=0,"",IFERROR(INDEX('Asignaciones Herramientas'!$H$5:$H$60,MATCH(K19,'Asignaciones Herramientas'!$A$5:$A$60,0)),"")) | G19: =IF(K19=0,"",IFERROR(INDEX('Asignaciones Herramientas'!$B$5:$B$60,MATCH(K19,'Asignaciones Herramientas'!$A$5:$A$60,0)),"")) | H19: =IF(OR(K19=0,IFERROR(INDEX('Asignaciones Herramientas'!$I$5:$I$60,MATCH(K19,'Asignaciones Herramientas'!$A$5:$A$60,0)),0)=0),"",INDEX('Asignaciones Herramientas'!$I$5:$I$60,MATCH(K19,'Asignaciones Herramientas'!$A$5:$A$60,0))) | I19: =IF(AND(D19="En Obra",H19<>"",H19<TODAY()),"RETRASADA","") | K19: =IFERROR(_xlfn.MAXIFS('Asignaciones Herramientas'!$A$5:$A$60,'Asignaciones Herramientas'!$C$5:$C$60,A19),0) -> 0 | L19: =IF(K19=0,"Sin Movimientos",IFERROR(INDEX('Asignaciones Herramientas'!$E$5:$E$60,MATCH(K19,'Asignaciones Herramientas'!$A$5:$A$60,0)),"")) -> Sin Movimientos

Sheet Catalogo Precios Venta
A1: Catalogo de Precios de Venta
A2: Precio por unidad de trabajo instalado (incluye material + mano de obra). Esta es tu lista de cobro al cliente.
A4: Codigo | B4: Concepto | C4: Unidad | D4: Precio Unitario Venta | E4: Categoria
A5: PV-001 | B5: Tuberia PVC 1/2" Instalada | C5: m | D5: 55 | E5: Plomeria
A6: PV-002 | B6: Tuberia PVC 3/4" Instalada | C6: m | D6: 68 | E6: Plomeria
A7: PV-003 | B7: Tuberia Conduit EMT 1/2" Instalada | C7: m | D7: 62 | E7: Electrico
A8: PV-004 | B8: Circuito Cal. 12 Instalado (m) | C8: m | D8: 28 | E8: Electrico
A9: PV-005 | B9: Circuito Cal. 10 Instalado (m) | C9: m | D9: 38 | E9: Electrico
A10: PV-006 | B10: Contacto Duplex Puesto | C10: pza | D10: 280 | E10: Electrico
A11: PV-007 | B11: Contacto GFCI Puesto | C11: pza | D11: 480 | E11: Electrico
A12: PV-008 | B12: Apagador Sencillo Puesto | C12: pza | D12: 250 | E12: Electrico
A13: PV-009 | B13: Luminaria LED Empotrable 6" Instalada | C13: pza | D13: 480 | E13: Electrico
A14: PV-010 | B14: Luminaria LED Panel 2x2 Instalada | C14: pza | D14: 780 | E14: Electrico
A15: PV-011 | B15: Valvula de Esfera 1/2" Instalada | C15: pza | D15: 180 | E15: Plomeria
A16: PV-012 | B16: Caja Registro Electrica Puesta | C16: pza | D16: 120 | E16: Electrico
... A24: PV-020 | B24: Proyecto Ejecutivo / Plano Electrico | C24: proyecto | D24: 4500 | E24: Servicio

Sheet Cotizador
A1: ='Datos Empresa'!B4 -> Instalaciones Electricas y Plomeria [Tu Empresa] | E1: COTIZACION
A2: ='Datos Empresa'!B6&" | "&'Datos Empresa'!B7&" | "&'Datos Empresa'!B8 -> | Escobedo, Nuevo Leon | | E2: No. Cotizacion: | F2: COT-2026-001
A3: ="RFC: "&'Datos Empresa'!B5 -> RFC: | E3: Fecha: | F3: =TODAY() -> 46220
E4: Valida hasta: | F4: =F3+'Datos Empresa'!B12 -> 46235
A6: DATOS DEL CLIENTE
A7: Cliente / Empresa: | D7: Telefono:
A8: Atencion a: | D8: Correo:
A9: Proyecto / Obra: | D9: Ubicacion:
A11: CONCEPTOS
A12: Codigo | B12: Concepto | C12: Unidad | D12: Cantidad | E12: Precio Catalogo (referencia) | F12: Precio Unitario Cotizado | G12: Importe
A13: PV-006 | B13: =IFERROR(INDEX('Catalogo Precios Venta'!$B$5:$B$24,MATCH(A13,'Catalogo Precios Venta'!$A$5:$A$24,0)),"") -> Contacto Duplex Puesto | C13: =IFERROR(INDEX('Catalogo Precios Venta'!$C$5:$C$24,MATCH(A13,'Catalogo Precios Venta'!$A$5:$A$24,0)),"") -> pza | D13: 8 | E13: =IFERROR(INDEX('Catalogo Precios Venta'!$D$5:$D$24,MATCH(A13,'Catalogo Precios Venta'!$A$5:$A$24,0)),"") -> 280 | F13: 280 | G13: =IF(D13="","",D13*F13) -> 2240
